<?xml version="1.0"?>
<robot name="mabi_mobile" xmlns:xacro="http://ros.org/wiki/xacro">
  <link name="base_link">
    <inertial>
      <mass value="19.7081876920141"/>
      <origin rpy="0 0 0" xyz="0.000734908043255453 -0.00273712217128683 0.281703769416384"/>
      <inertia ixx="0.28106977770538" ixy="0.0118832421775035" ixz="0.00400462276269483" iyy="0.509161157694943" iyz="4.00678293024184E-05" izz="0.662015704059806"/>
    </inertial>
    <visual>
      <origin rpy="0 0 0" xyz="0 0 0"/>
      <geometry>
        <mesh filename="meshes/base.stl"/>
      </geometry>
      <material name="">
        <color rgba="0.752941176470588 0.752941176470588 0.752941176470588 1"/>
      </material>
    </visual>
    <collision>
      <origin rpy="0 0 0" xyz="0 0 0.3393"/>
      <geometry>
        <box size="1.020 0.585 0.6785"/>
      </geometry>
    </collision>
  </link>
  <joint name="fl_wheel_joint" type="fixed">
    <parent link="base_link"/>
    <child link="fl_wheel"/>
    <axis xyz="0 1 0"/>
    <origin rpy="0 0 0" xyz="0.305 0.3 0"/>
  </joint>
  <link name="fl_wheel">
    <inertial>
      <mass value="0.42252"/>
      <origin rpy="0 0 0" xyz="8.032E-09 8.9348E-08 1.7911E-07"/>
      <inertia ixx="0.00015702" ixy="9.8304E-10" ixz="-2.3564E-10" iyy="0.00012074" iyz="6.991E-10" izz="0.00015702"/>
    </inertial>
    <visual>
      <origin rpy="0 0 0" xyz="0 0 0"/>
      <geometry>
        <mesh filename="meshes/wheel.stl"/>
      </geometry>
      <material name="">
        <color rgba="1 1 0.50196 1"/>
      </material>
    </visual>
    <collision>
      <origin rpy="1.5708 0 0" xyz="0 0 0"/>
      <geometry>
        <cylinder length="0.08" radius="0.075"/>
      </geometry>
    </collision>
  </link>
  <joint name="fr_wheel_joint" type="fixed">
    <parent link="base_link"/>
    <child link="fr_wheel"/>
    <axis xyz="0 1 0"/>
    <origin rpy="0 0 0" xyz="0.305 -0.3 0"/>
  </joint>
  <link name="fr_wheel">
    <inertial>
      <mass value="0.42252"/>
      <origin rpy="0 0 0" xyz="8.032E-09 8.9348E-08 1.7911E-07"/>
      <inertia ixx="0.00015702" ixy="9.8304E-10" ixz="-2.3564E-10" iyy="0.00012074" iyz="6.991E-10" izz="0.00015702"/>
    </inertial>
    <visual>
      <origin rpy="0 0 0" xyz="0 0 0"/>
      <geometry>
        <mesh filename="meshes/wheel.stl"/>
      </geometry>
      <material name="">
        <color rgba="1 1 0.50196 1"/>
      </material>
    </visual>
    <collision>
      <origin rpy="1.5708 0 0" xyz="0 0 0"/>
      <geometry>
        <cylinder length="0.08" radius="0.075"/>
      </geometry>
    </collision>
  </link>
  <joint name="rl_wheel_joint" type="fixed">
    <parent link="base_link"/>
    <child link="rl_wheel"/>
    <axis xyz="0 1 0"/>
    <origin rpy="0 0 0" xyz="-0.305 0.3 0"/>
  </joint>
  <link name="rl_wheel">
    <inertial>
      <mass value="0.42252"/>
      <origin rpy="0 0 0" xyz="8.032E-09 8.9348E-08 1.7911E-07"/>
      <inertia ixx="0.00015702" ixy="9.8304E-10" ixz="-2.3564E-10" iyy="0.00012074" iyz="6.991E-10" izz="0.00015702"/>
    </inertial>
    <visual>
      <origin rpy="0 0 0" xyz="0 0 0"/>
      <geometry>
        <mesh filename="meshes/wheel.stl"/>
      </geometry>
      <material name="">
        <color rgba="1 1 0.50196 1"/>
      </material>
    </visual>
    <collision>
      <origin rpy="1.5708 0 0" xyz="0 0 0"/>
      <geometry>
        <cylinder length="0.08" radius="0.075"/>
      </geometry>
    </collision>
  </link>
  <joint name="rr_wheel_joint" type="fixed">
    <parent link="base_link"/>
    <child link="rr_wheel"/>
    <axis xyz="0 1 0"/>
    <origin rpy="0 0 0" xyz="-0.305 -0.3 0"/>
  </joint>
  <link name="rr_wheel">
    <inertial>
      <mass value="0.42252"/>
      <origin rpy="0 0 0" xyz="8.032E-09 8.9348E-08 1.7911E-07"/>
      <inertia ixx="0.00015702" ixy="9.8304E-10" ixz="-2.3564E-10" iyy="0.00012074" iyz="6.991E-10" izz="0.00015702"/>
    </inertial>
    <visual>
      <origin rpy="0 0 0" xyz="0 0 0"/>
      <geometry>
        <mesh filename="meshes/wheel.stl"/>
      </geometry>
      <material name="">
        <color rgba="1 1 0.50196 1"/>
      </material>
    </visual>
    <collision>
      <origin rpy="1.5708 0 0" xyz="0 0 0"/>
      <geometry>
        <cylinder length="0.08" radius="0.075"/>
      </geometry>
    </collision>
  </link>
  <joint name="base_link_arm_base_joint" type="fixed">
    <parent link="base_link"/>
    <child link="arm_base"/>
    <origin rpy="0 0 0" xyz="0.3 0 0.69"/>
  </joint>
  <link name="arm_base">
    <inertial>
      <mass value="3.7"/>
      <origin rpy="0 0 0" xyz="0.0 -0.0 0.09"/>
      <inertia ixx="0.02" ixy="0.0" ixz="0.0" iyy="0.02" iyz="0.0" izz="0.01"/>
    </inertial>
    <visual>
      <origin rpy="0 0 0" xyz="0 0 0"/>
      <geometry>
        <mesh filename="meshes/rizon4s/visual/link0.obj"/>
      </geometry>
      <material name="rizon_light_grey"/>
    </visual>
    <collision>
      <origin rpy="0 0 0" xyz="0 0 0"/>
      <geometry>
        <mesh filename="meshes/rizon4s/collision/link0.stl"/>
      </geometry>
    </collision>
  </link>
  <joint name="joint1" type="revolute">
    <parent link="arm_base"/>
    <child link="link1"/>
    <axis xyz="0 0 1"/>
    <limit effort="123" lower="-2.7925" upper="2.7925" velocity="2.0944"/>
    <origin xyz="0.0 0.0 0.155" rpy="0.0 0.0 -3.141592653589793"/>
  </joint>
  <link name="link1">
    <inertial>
      <mass value="3.7"/>
      <origin rpy="0 0 0" xyz="0.0 0.01 0.15"/>
      <inertia ixx="0.03" ixy="0.0" ixz="0.0" iyy="0.03" iyz="0.0" izz="0.01"/>
    </inertial>
    <visual>
      <origin rpy="0 0 0" xyz="0 0 0"/>
      <geometry>
        <mesh filename="meshes/rizon4s/visual/link1.obj"/>
      </geometry>
      <material name="rizon_light_grey"/>
    </visual>
    <collision>
      <origin rpy="0 0 0" xyz="0 0 0"/>
      <geometry>
        <mesh filename="meshes/rizon4s/collision/link1.stl"/>
      </geometry>
    </collision>
  </link>
  <joint name="joint2" type="revolute">
    <parent link="link1"/>
    <child link="link2"/>
    <axis xyz="0 1 0"/>
    <limit effort="123" lower="-2.2689" upper="2.2689" velocity="2.0944"/>
    <origin xyz="0.0 0.03 0.21" rpy="0.0 0.0 0.0"/>
  </joint>
  <link name="link2">
    <inertial>
      <mass value="2.7"/>
      <origin rpy="0 0 0" xyz="0.0 0.04 0.1"/>
      <inertia ixx="0.02" ixy="0.0" ixz="0.0" iyy="0.02" iyz="-0.0" izz="0.0"/>
    </inertial>
    <visual>
      <origin rpy="0 0 0" xyz="0 0 0"/>
      <geometry>
        <mesh filename="meshes/rizon4s/visual/link2.obj"/>
      </geometry>
      <material name="rizon_light_grey"/>
    </visual>
    <collision>
      <origin rpy="0 0 0" xyz="0 0 0"/>
      <geometry>
        <mesh filename="meshes/rizon4s/collision/link2.stl"/>
      </geometry>
    </collision>
  </link>
  <joint name="joint3" type="revolute">
    <parent link="link2"/>
    <child link="link3"/>
    <axis xyz="0 0 1"/>
    <limit effort="64" lower="-2.9671" upper="2.9671" velocity="2.4435"/>
    <origin xyz="0.0 0.035 0.205" rpy="0.0 0.0 0.0"/>
  </joint>
  <link name="link3">
    <inertial>
      <mass value="2.4"/>
      <origin rpy="0 0 0" xyz="-0.01 -0.0 0.13"/>
      <inertia ixx="0.01" ixy="0.0" ixz="-0.0" iyy="0.01" iyz="-0.0" izz="0.0"/>
    </inertial>
    <visual>
      <origin rpy="0 0 0" xyz="0 0 0"/>
      <geometry>
        <mesh filename="meshes/rizon4s/visual/link3.obj"/>
      </geometry>
      <material name="rizon_light_grey"/>
    </visual>
    <collision>
      <origin rpy="0 0 0" xyz="0 0 0"/>
      <geometry>
        <mesh filename="meshes/rizon4s/collision/link3.stl"/>
      </geometry>
    </collision>
  </link>
  <joint name="joint4" type="revolute">
    <parent link="link3"/>
    <child link="link4"/>
    <axis xyz="0 1 0"/>
    <limit effort="64" lower="-1.8675" upper="2.6878" velocity="2.4435"/>
    <origin xyz="-0.02 -0.03 0.19" rpy="0.0 0.0 -3.141592653589793"/>
  </joint>
  <link name="link4">
    <inertial>
      <mass value="2.4"/>
      <origin rpy="0 0 0" xyz="-0.01 0.03 0.1"/>
      <inertia ixx="0.02" ixy="0.0" ixz="-0.0" iyy="0.02" iyz="-0.0" izz="0.0"/>
    </inertial>
    <visual>
      <origin rpy="0 0 0" xyz="0 0 0"/>
      <geometry>
        <mesh filename="meshes/rizon4s/visual/link4.obj"/>
      </geometry>
      <material name="rizon_light_grey"/>
    </visual>
    <collision>
      <origin rpy="0 0 0" xyz="0 0 0"/>
      <geometry>
        <mesh filename="meshes/rizon4s/collision/link4.stl"/>
      </geometry>
    </collision>
  </link>
  <joint name="joint5" type="revolute">
    <parent link="link4"/>
    <child link="link5"/>
    <axis xyz="0 0 1"/>
    <limit effort="39" lower="-2.9671" upper="2.9671" velocity="4.8869"/>
    <origin xyz="-0.02 0.025 0.195" rpy="0.0 0.0 -3.141592653589793"/>
  </joint>
  <link name="link5">
    <inertial>
      <mass value="2.4"/>
      <origin rpy="0 0 0" xyz="-0.0 0.0 0.13"/>
      <inertia ixx="0.01" ixy="0.0" ixz="0.0" iyy="0.01" iyz="0.0" izz="0.0"/>
    </inertial>
    <visual>
      <origin rpy="0 0 0" xyz="0 0 0"/>
      <geometry>
        <mesh filename="meshes/rizon4s/visual/link5.obj"/>
      </geometry>
      <material name="rizon_light_grey"/>
    </visual>
    <collision>
      <origin rpy="0 0 0" xyz="0 0 0"/>
      <geometry>
        <mesh filename="meshes/rizon4s/collision/link5.stl"/>
      </geometry>
    </collision>
  </link>
  <joint name="joint6" type="revolute">
    <parent link="link5"/>
    <child link="link6"/>
    <axis xyz="0 1 0"/>
    <limit effort="39" lower="-1.3963" upper="4.5379" velocity="4.8869"/>
    <origin xyz="0.0 0.03 0.19" rpy="0.0 0.0 0.0"/>
  </joint>
  <link name="link6">
    <inertial>
      <mass value="2.1"/>
      <origin rpy="0 0 0" xyz="-0.01 0.06 0.07"/>
      <inertia ixx="0.01" ixy="-0.0" ixz="-0.0" iyy="0.01" iyz="0.0" izz="0.0"/>
    </inertial>
    <visual>
      <origin rpy="0 0 0" xyz="0 0 0"/>
      <geometry>
        <mesh filename="meshes/rizon4s/visual/link6.obj"/>
      </geometry>
      <material name="rizon_light_grey"/>
    </visual>
    <collision>
      <origin rpy="0 0 0" xyz="0 0 0"/>
      <geometry>
        <mesh filename="meshes/rizon4s/collision/link6.stl"/>
      </geometry>
    </collision>
  </link>
  <joint name="joint7" type="revolute">
    <parent link="link6"/>
    <child link="link7"/>
    <axis xyz="0 0 1"/>
    <limit effort="39" lower="-2.9671" upper="2.9671" velocity="4.8869"/>
    <origin xyz="-0.055 0.07 0.11" rpy="0.0 -1.5707963478683205 0.0"/>
  </joint>
  <link name="link7">
    <inertial>
      <mass value="2.27"/>
      <origin rpy="0 0 0" xyz="0.0 0.0 0.05"/>
      <inertia ixx="0.0" ixy="0.0" ixz="0.0" iyy="0.0" iyz="0.0" izz="0.0"/>
    </inertial>
    <visual>
      <origin rpy="0 0 0" xyz="0 0 0"/>
      <geometry>
        <mesh filename="meshes/rizon4s/visual/link7.obj"/>
      </geometry>
      <material name="rizon_light_grey"/>
    </visual>
    <collision>
      <origin rpy="0 0 0" xyz="0 0 0"/>
      <geometry>
        <mesh filename="meshes/rizon4s/collision/link7.stl"/>
      </geometry>
    </collision>
  </link>
  <joint name="link7_to_flange" type="fixed">
    <parent link="link7"/>
    <child link="flange"/>
    <origin xyz="0.0 0.0 0.124" rpy="0.0 0.0 -3.141592653589793"/>
  </joint>
  <link name="flange">
  </link>
  <material name="rizon_blue">
    <color rgba="0.0 0.0 1.0 0.5"/>
  </material>
  <material name="rizon_light_grey">
    <color rgba="0.7 0.7 0.7 1.0"/>
  </material>
  <material name="rizon_dark_grey">
    <color rgba="0.4 0.4 0.4 1.0"/>
  </material>
  <material name="rizon_white">
    <color rgba="1.0 1.0 1.0 1.0"/>
  </material>
</robot>
