<?xml version="1.0"?>
<robot name="mabi_mobile" xmlns:xacro="http://ros.org/wiki/xacro">
  <link name="base_link">
    <visual>
      <origin xyz="0 0 0.299" rpy="0 0 0"/>
      <geometry>
        <box size="0.8 0.7 0.02"/>
      </geometry>
    </visual>
    <collision>
      <origin xyz="0 0 0.299" rpy="0 0 0"/>
      <geometry>
        <box size="0.8 0.7 0.02"/>
      </geometry>
    </collision>
    <visual>
      <origin xyz="0.39 0 0.1445" rpy="0 0 0"/>
      <geometry>
        <box size="0.02 0.7 0.289"/>
      </geometry>
    </visual>
    <collision>
      <origin xyz="0.39 0 0.1445" rpy="0 0 0"/>
      <geometry>
        <box size="0.02 0.7 0.289"/>
      </geometry>
    </collision>
    <visual>
      <origin xyz="-0.39 0 0.1445" rpy="0 0 0"/>
      <geometry>
        <box size="0.02 0.7 0.289"/>
      </geometry>
    </visual>
    <collision>
      <origin xyz="-0.39 0 0.1445" rpy="0 0 0"/>
      <geometry>
        <box size="0.02 0.7 0.289"/>
      </geometry>
    </collision>
    <visual>
      <origin xyz="0 0.34 0.1445" rpy="0 0 0"/>
      <geometry>
        <box size="0.76 0.02 0.289"/>
      </geometry>
    </visual>
    <collision>
      <origin xyz="0 0.34 0.1445" rpy="0 0 0"/>
      <geometry>
        <box size="0.76 0.02 0.289"/>
      </geometry>
    </collision>
    <visual>
      <origin xyz="0 -0.34 0.1445" rpy="0 0 0"/>
      <geometry>
        <box size="0.76 0.02 0.289"/>
      </geometry>
    </visual>
    <collision>
      <origin xyz="0 -0.34 0.1445" rpy="0 0 0"/>
      <geometry>
        <box size="0.76 0.02 0.289"/>
      </geometry>
    </collision>
  </link>
  <joint name="base_link_arm_base_joint" type="fixed">
    <parent link="base_link"/>
    <child link="arm_base"/>
    <origin xyz="0 0 0.309" rpy="0 0 0"/>
  </joint>
  <link name="arm_base">
    <inertial>
      <mass value="3.7"/>
      <origin rpy="0 0 0" xyz="0.0 -0.0 0.09"/>
      <inertia ixx="0.02" ixy="0.0" ixz="0.0" iyy="0.02" iyz="0.0" izz="0.01"/>
    </inertial>
    <visual>
      <origin rpy="0 0 0" xyz="0 0 0"/>
      <geometry>
        <mesh filename="meshes/rizon4s/visual/link0.obj"/>
      </geometry>
      <material name="rizon_light_grey"/>
    </visual>
    <collision>
      <origin rpy="0 0 0" xyz="0 0 0"/>
      <geometry>
        <mesh filename="meshes/rizon4s/collision/link0.stl"/>
      </geometry>
    </collision>
  </link>
  <joint name="joint1" type="revolute">
    <parent link="arm_base"/>
    <child link="link1"/>
    <axis xyz="0 0 1"/>
    <limit effort="123" lower="-2.7925" upper="2.7925" velocity="2.0944"/>
    <origin xyz="0.0 0.0 0.155" rpy="0.0 0.0 -3.141592653589793"/>
  </joint>
  <link name="link1">
    <inertial>
      <mass value="3.7"/>
      <origin rpy="0 0 0" xyz="0.0 0.01 0.15"/>
      <inertia ixx="0.03" ixy="0.0" ixz="0.0" iyy="0.03" iyz="0.0" izz="0.01"/>
    </inertial>
    <visual>
      <origin rpy="0 0 0" xyz="0 0 0"/>
      <geometry>
        <mesh filename="meshes/rizon4s/visual/link1.obj"/>
      </geometry>
      <material name="rizon_light_grey"/>
    </visual>
    <collision>
      <origin rpy="0 0 0" xyz="0 0 0"/>
      <geometry>
        <mesh filename="meshes/rizon4s/collision/link1.stl"/>
      </geometry>
    </collision>
  </link>
  <joint name="joint2" type="revolute">
    <parent link="link1"/>
    <child link="link2"/>
    <axis xyz="0 1 0"/>
    <limit effort="123" lower="-2.2689" upper="2.2689" velocity="2.0944"/>
    <origin xyz="0.0 0.03 0.21" rpy="0.0 0.0 0.0"/>
  </joint>
  <link name="link2">
    <inertial>
      <mass value="2.7"/>
      <origin rpy="0 0 0" xyz="0.0 0.04 0.1"/>
      <inertia ixx="0.02" ixy="0.0" ixz="0.0" iyy="0.02" iyz="-0.0" izz="0.0"/>
    </inertial>
    <visual>
      <origin rpy="0 0 0" xyz="0 0 0"/>
      <geometry>
        <mesh filename="meshes/rizon4s/visual/link2.obj"/>
      </geometry>
      <material name="rizon_light_grey"/>
    </visual>
    <collision>
      <origin rpy="0 0 0" xyz="0 0 0"/>
      <geometry>
        <mesh filename="meshes/rizon4s/collision/link2.stl"/>
      </geometry>
    </collision>
  </link>
  <joint name="joint3" type="revolute">
    <parent link="link2"/>
    <child link="link3"/>
    <axis xyz="0 0 1"/>
    <limit effort="64" lower="-2.9671" upper="2.9671" velocity="2.4435"/>
    <origin xyz="0.0 0.035 0.205" rpy="0.0 0.0 0.0"/>
  </joint>
  <link name="link3">
    <inertial>
      <mass value="2.4"/>
      <origin rpy="0 0 0" xyz="-0.01 -0.0 0.13"/>
      <inertia ixx="0.01" ixy="0.0" ixz="-0.0" iyy="0.01" iyz="-0.0" izz="0.0"/>
    </inertial>
    <visual>
      <origin rpy="0 0 0" xyz="0 0 0"/>
      <geometry>
        <mesh filename="meshes/rizon4s/visual/link3.obj"/>
      </geometry>
      <material name="rizon_light_grey"/>
    </visual>
    <collision>
      <origin rpy="0 0 0" xyz="0 0 0"/>
      <geometry>
        <mesh filename="meshes/rizon4s/collision/link3.stl"/>
      </geometry>
    </collision>
  </link>
  <joint name="joint4" type="revolute">
    <parent link="link3"/>
    <child link="link4"/>
    <axis xyz="0 1 0"/>
    <limit effort="64" lower="-1.8675" upper="2.6878" velocity="2.4435"/>
    <origin xyz="-0.02 -0.03 0.19" rpy="0.0 0.0 -3.141592653589793"/>
  </joint>
  <link name="link4">
    <inertial>
      <mass value="2.4"/>
      <origin rpy="0 0 0" xyz="-0.01 0.03 0.1"/>
      <inertia ixx="0.02" ixy="0.0" ixz="-0.0" iyy="0.02" iyz="-0.0" izz="0.0"/>
    </inertial>
    <visual>
      <origin rpy="0 0 0" xyz="0 0 0"/>
      <geometry>
        <mesh filename="meshes/rizon4s/visual/link4.obj"/>
      </geometry>
      <material name="rizon_light_grey"/>
    </visual>
    <collision>
      <origin rpy="0 0 0" xyz="0 0 0"/>
      <geometry>
        <mesh filename="meshes/rizon4s/collision/link4.stl"/>
      </geometry>
    </collision>
  </link>
  <joint name="joint5" type="revolute">
    <parent link="link4"/>
    <child link="link5"/>
    <axis xyz="0 0 1"/>
    <limit effort="39" lower="-2.9671" upper="2.9671" velocity="4.8869"/>
    <origin xyz="-0.02 0.025 0.195" rpy="0.0 0.0 -3.141592653589793"/>
  </joint>
  <link name="link5">
    <inertial>
      <mass value="2.4"/>
      <origin rpy="0 0 0" xyz="-0.0 0.0 0.13"/>
      <inertia ixx="0.01" ixy="0.0" ixz="0.0" iyy="0.01" iyz="0.0" izz="0.0"/>
    </inertial>
    <visual>
      <origin rpy="0 0 0" xyz="0 0 0"/>
      <geometry>
        <mesh filename="meshes/rizon4s/visual/link5.obj"/>
      </geometry>
      <material name="rizon_light_grey"/>
    </visual>
    <collision>
      <origin rpy="0 0 0" xyz="0 0 0"/>
      <geometry>
        <mesh filename="meshes/rizon4s/collision/link5.stl"/>
      </geometry>
    </collision>
  </link>
  <joint name="joint6" type="revolute">
    <parent link="link5"/>
    <child link="link6"/>
    <axis xyz="0 1 0"/>
    <limit effort="39" lower="-1.3963" upper="4.5379" velocity="4.8869"/>
    <origin xyz="0.0 0.03 0.19" rpy="0.0 0.0 0.0"/>
  </joint>
  <link name="link6">
    <inertial>
      <mass value="2.1"/>
      <origin rpy="0 0 0" xyz="-0.01 0.06 0.07"/>
      <inertia ixx="0.01" ixy="-0.0" ixz="-0.0" iyy="0.01" iyz="0.0" izz="0.0"/>
    </inertial>
    <visual>
      <origin rpy="0 0 0" xyz="0 0 0"/>
      <geometry>
        <mesh filename="meshes/rizon4s/visual/link6.obj"/>
      </geometry>
      <material name="rizon_light_grey"/>
    </visual>
    <collision>
      <origin rpy="0 0 0" xyz="0 0 0"/>
      <geometry>
        <mesh filename="meshes/rizon4s/collision/link6.stl"/>
      </geometry>
    </collision>
  </link>
  <joint name="joint7" type="revolute">
    <parent link="link6"/>
    <child link="link7"/>
    <axis xyz="0 0 1"/>
    <limit effort="39" lower="-2.9671" upper="2.9671" velocity="4.8869"/>
    <origin xyz="-0.055 0.07 0.11" rpy="0.0 -1.5707963478683205 0.0"/>
  </joint>
  <link name="link7">
    <inertial>
      <mass value="1.4"/>
      <origin rpy="0 0 0" xyz="0.0 0.0 0.05"/>
      <inertia ixx="0.0" ixy="0.0" ixz="0.0" iyy="0.0" iyz="0.0" izz="0.0"/>
    </inertial>
    <visual>
      <origin rpy="0 0 0" xyz="0 0 0"/>
      <geometry>
        <mesh filename="meshes/rizon4s/visual/link7.obj"/>
      </geometry>
      <material name="rizon_light_grey"/>
    </visual>
    <collision>
      <origin rpy="0 0 0" xyz="0 0 0"/>
      <geometry>
        <mesh filename="meshes/rizon4s/collision/link7.stl"/>
      </geometry>
    </collision>
  </link>
  <joint name="link7_to_flange" type="fixed">
    <parent link="link7"/>
    <child link="flange"/>
    <origin xyz="0.0 0.0 0.124" rpy="0.0 0.0 -3.141592653589793"/>
  </joint>
  <link name="flange"/>
  <joint name="hingejoint" type="fixed">
    <parent link="base_link"/>
    <child link="cw_hr_link"/>
    <axis xyz="0 1 0"/>
    <origin xyz="-0.25 -0.185 0.005" rpy="0 0 0"/>
  </joint>
  <link name="cw_hr_link">
    <visual>
      <origin xyz="0 0 0" rpy="1.570796 0 0"/>
      <geometry>
        <cylinder radius="0.05" length="0.04"/>
      </geometry>
    </visual>
    <collision>
      <origin xyz="0 0 0" rpy="1.570796 0 0"/>
      <geometry>
        <cylinder radius="0.05" length="0.04"/>
      </geometry>
    </collision>
  </link>
  <joint name="hingejoint_0" type="fixed">
    <parent link="base_link"/>
    <child link="cw_hl_link"/>
    <axis xyz="0 1 0"/>
    <origin xyz="-0.25 0.185 0.005" rpy="0 0 0"/>
  </joint>
  <link name="cw_hl_link">
    <visual>
      <origin xyz="0 0 0" rpy="1.570796 0 0"/>
      <geometry>
        <cylinder radius="0.05" length="0.04"/>
      </geometry>
    </visual>
    <collision>
      <origin xyz="0 0 0" rpy="1.570796 0 0"/>
      <geometry>
        <cylinder radius="0.05" length="0.04"/>
      </geometry>
    </collision>
  </link>
  <joint name="hingejoint_1" type="fixed">
    <parent link="base_link"/>
    <child link="cw_fr_link"/>
    <axis xyz="0 1 0"/>
    <origin xyz="0.25 -0.185 0.005" rpy="0 0 0"/>
  </joint>
  <link name="cw_fr_link">
    <visual>
      <origin xyz="0 0 0" rpy="1.570796 0 0"/>
      <geometry>
        <cylinder radius="0.05" length="0.04"/>
      </geometry>
    </visual>
    <collision>
      <origin xyz="0 0 0" rpy="1.570796 0 0"/>
      <geometry>
        <cylinder radius="0.05" length="0.04"/>
      </geometry>
    </collision>
  </link>
  <joint name="hingejoint_2" type="fixed">
    <parent link="base_link"/>
    <child link="cw_fl_link"/>
    <axis xyz="0 1 0"/>
    <origin xyz="0.25 0.185 0.005" rpy="0 0 0"/>
  </joint>
  <link name="cw_fl_link">
    <visual>
      <origin xyz="0 0 0" rpy="1.570796 0 0"/>
      <geometry>
        <cylinder radius="0.05" length="0.04"/>
      </geometry>
    </visual>
    <collision>
      <origin xyz="0 0 0" rpy="1.570796 0 0"/>
      <geometry>
        <cylinder radius="0.05" length="0.04"/>
      </geometry>
    </collision>
  </link>
  <joint name="R_WHEEL" type="fixed">
    <parent link="base_link"/>
    <child link="R_WHEEL"/>
    <axis xyz="0 1 0"/>
    <limit effort="50" velocity="10"/>
    <origin xyz="0 -0.29 0.1" rpy="0 0 0"/>
  </joint>
  <link name="R_WHEEL">
    <visual>
      <origin xyz="0 0 0" rpy="1.570796 0 0"/>
      <geometry>
        <cylinder radius="0.15" length="0.06"/>
      </geometry>
    </visual>
    <collision>
      <origin xyz="0 0 0" rpy="1.570796 0 0"/>
      <geometry>
        <cylinder radius="0.15" length="0.06"/>
      </geometry>
    </collision>
  </link>
  <joint name="L_WHEEL" type="fixed">
    <parent link="base_link"/>
    <child link="L_WHEEL"/>
    <axis xyz="0 1 0"/>
    <limit effort="50" velocity="10"/>
    <origin xyz="0 0.29 0.1" rpy="0 0 0"/>
  </joint>
  <link name="L_WHEEL">
    <visual>
      <origin xyz="0 0 0" rpy="1.570796 0 0"/>
      <geometry>
        <cylinder radius="0.15" length="0.06"/>
      </geometry>
    </visual>
    <collision>
      <origin xyz="0 0 0" rpy="1.570796 0 0"/>
      <geometry>
        <cylinder radius="0.15" length="0.06"/>
      </geometry>
    </collision>
  </link>
  <link name="base_link_inertia">
  </link>
  <joint name="base_link_base_link_inertia_joint" type="fixed">
    <parent link="base_link"/>
    <child link="base_link_inertia"/>
    <origin xyz="0 0 0.1545" rpy="0 0 0"/>
  </joint>
  <link name="base_acc">
  </link>
  <joint name="base_link_base_acc_joint" type="fixed">
    <parent link="base_link"/>
    <child link="base_acc"/>
    <origin xyz="0 0 0" rpy="0 0 0"/>
  </joint>
  <link name="base_gyro">
  </link>
  <joint name="base_link_base_gyro_joint" type="fixed">
    <parent link="base_link"/>
    <child link="base_gyro"/>
    <origin xyz="0 0 0" rpy="0 0 0"/>
  </joint>
  <link name="base_inertial">
  </link>
  <joint name="base_link_base_inertial_joint" type="fixed">
    <parent link="base_link"/>
    <child link="base_inertial"/>
    <origin xyz="0 0 0" rpy="0 0 0"/>
  </joint>
  <link name="base_gps">
  </link>
  <joint name="base_link_base_gps_joint" type="fixed">
    <parent link="base_link"/>
    <child link="base_gps"/>
    <origin xyz="0 0 0" rpy="0 0 0"/>
  </joint>
  <material name="rizon_blue">
    <color rgba="0.0 0.0 1.0 0.5"/>
  </material>
  <material name="rizon_light_grey">
    <color rgba="0.7 0.7 0.7 1.0"/>
  </material>
  <material name="rizon_dark_grey">
    <color rgba="0.4 0.4 0.4 1.0"/>
  </material>
  <material name="rizon_white">
    <color rgba="1.0 1.0 1.0 1.0"/>
  </material>
</robot>
